<?xml version="1.0" ?>

<robot name="stuart" xmlns:xacro="http://wiki.ros.org/xacro">

  <material name="grey">
    <color rgba="0.5 0.5 0.5 1"/>
  </material>
  <material name="dark_grey">
    <color rgba="0.3 0.3 0.3 1"/>
  </material>
  <material name="red">
    <color rgba="1.0 0.0 0.0 1"/>
  </material>
  <material name="green">
    <color rgba="0.0 1.0 0.0 1"/>
  </material>
  <material name="black">
    <color rgba="0.1 0.1 0.1 1"/>
  </material>
  <material name="light_grey">
    <color rgba="0.8 0.8 0.8 1"/>
  </material>
  <material name="blue">
    <color rgba="0.0 0.0 0.8 1.0"/>
  </material>
  <material name="silver">
    <color rgba="0.913725490196 0.913725490196 0.847058823529 1.0"/>
  </material>
  <material name="orange">
    <color rgba="1.0 0.423529411765 0.0392156862745 1.0"/>
  </material>
  <material name="brown">
    <color rgba="0.870588235294 0.811764705882 0.764705882353 1.0"/>
  </material>
  <material name="white">
    <color rgba="1.0 1.0 1.0 1.0"/>
  </material>

  <link name="world"/>
   <joint name="reference" type="fixed">
     <origin xyz="0.0 0.0 0.5"/>
     <parent link="world"/>
     <child link="chassis"/>
   </joint>

  <link name="chassis">
    <visual>
      <origin rpy="0 0 0" xyz="0 0 0"/>
      <geometry>
        <!--<mesh filename="package://stuart_urdf/meshes/chassis.dae"/> -->
	<box size="0.2 0.105 0.01"/>
      </geometry>
      <material name="silver"/>
    </visual>
    <collision>
      <origin rpy="0 0 0" xyz="0 0 0"/>
      <geometry>
        <box size="0.2 0.105 0.01"/>
      </geometry>
    </collision>
    <inertial>
      <origin rpy="0 0 0" xyz="0.002284 -4.1e-05 0.025165"/>
      <mass value="1.065"/>
      <inertia ixx="0.073348887" ixy="0.00030338" ixz="0.001918218" iyy="0.250684593" iyz="-7.5402e-05" izz="0.254469458"/>
    </inertial>
  </link>

  <!--<link name="pi">
    <visual>
      <origin rpy="0 0 0" xyz="0 0 0"/>
      <geometry>
	<box size="0.06 0.09 0.024"/>
      </geometry>
      <material name="orange"/>
    </visual>
    <collision>
      <origin rpy="0 0 0" xyz="0 0 0"/>
      <geometry>
        <box size="0.06 0.09 0.024"/>
      </geometry>
    </collision>
    <inertial>
      <origin rpy="0 0 0" xyz="0.002284 -4.1e-05 0.025165"/>
      <mass value="0.045"/>
      <inertia ixx="0.073348887" ixy="0.00030338" ixz="0.001918218" iyy="0.250684593" iyz="-7.5402e-05" izz="0.254469458"/>
    </inertial>
  </link>
  <joint name="pi_chassis" type="fixed">
    <parent link="chassis"/>
    <child link="pi"/>
    <origin rpy="0 0 0" xyz="-0.055 0 0.017"/>
    <axis xyz="0 0 0"/>
    <dynamics damping="0" friction="0"/>
    <limit effort="100" velocity="100"/>
  </joint>

  <link name="imu">
    <visual>
      <origin rpy="0 0 0" xyz="0 0 0"/>
      <geometry>
	<box size="0.051 0.036 0.015"/>
      </geometry>
      <material name="orange"/>
    </visual>
    <collision>
      <origin rpy="0 0 0" xyz="0 0 0"/>
      <geometry>
        <box size="0.051 0.036 0.015"/>
      </geometry>
    </collision>
    <inertial>
      <origin rpy="0 0 0" xyz="0.002284 -4.1e-05 0.025165"/>
      <mass value="0.05"/>
      <inertia ixx="0.073348887" ixy="0.00030338" ixz="0.001918218" iyy="0.250684593" iyz="-7.5402e-05" izz="0.254469458"/>
    </inertial>
  </link>
  <joint name="imu_chassis" type="fixed">
    <parent link="chassis"/>
    <child link="imu"/>
    <origin rpy="0 0 0" xyz="0.0705 0 0.0125"/>
    <axis xyz="0 0 0"/>
    <dynamics damping="0" friction="0"/>
    <limit effort="100" velocity="100"/>
  </joint>

  <link name="servodriver">
    <visual>
      <origin rpy="0 0 0" xyz="0 0 0"/>
      <geometry>
	<box size="0.024 0.06 0.024"/>
      </geometry>
      <material name="orange"/>
    </visual>
    <collision>
      <origin rpy="0 0 0" xyz="0 0 0"/>
      <geometry>
        <box size="0.024 0.06 0.024"/>
      </geometry>
    </collision>
    <inertial>
      <origin rpy="0 0 0" xyz="0.002284 -4.1e-05 0.025165"/>
      <mass value="0.009"/>
      <inertia ixx="0.073348887" ixy="0.00030338" ixz="0.001918218" iyy="0.250684593" iyz="-7.5402e-05" izz="0.254469458"/>
    </inertial>
  </link>
  <joint name="servodriver_chassis" type="fixed">
    <parent link="chassis"/>
    <child link="servodriver"/>
    <origin rpy="0 0 0" xyz="0.045 0 0.037"/>
    <axis xyz="0 0 0"/>
    <dynamics damping="0" friction="0"/>
    <limit effort="100" velocity="100"/>
  </joint>-->




  <link name="motorFL1">
    <visual>
      <origin rpy="0 0 0" xyz="0 0 0"/>
      <geometry>
	<box size="0.04 0.04 0.02"/>
      </geometry>
      <material name="silver"/>
    </visual>
    <collision>
      <origin rpy="0 0 0" xyz="0 0 0"/>
      <geometry>
	<box size="0.04 0.04 0.02"/>
      </geometry>
    </collision>
    <inertial>
      <origin rpy="0 0 0" xyz="0.002284 -4.1e-05 0.025165"/>
      <mass value="0.057"/>
      <inertia ixx="0.073348887" ixy="0.00030338" ixz="0.001918218" iyy="0.250684593" iyz="-7.5402e-05" izz="0.254469458"/>
    </inertial>
  </link>

  <link name="motorFR1">
    <visual>
      <origin rpy="0 0 0" xyz="0 0 0"/>
      <geometry>
	<box size="0.04 0.04 0.02"/>
      </geometry>
      <material name="silver"/>
    </visual>
    <collision>
      <origin rpy="0 0 0" xyz="0 0 0"/>
      <geometry>
	<box size="0.04 0.04 0.02"/>
      </geometry>
    </collision>
    <inertial>
      <origin rpy="0 0 0" xyz="0.002284 -4.1e-05 0.025165"/>
      <mass value="0.057"/>
      <inertia ixx="0.073348887" ixy="0.00030338" ixz="0.001918218" iyy="0.250684593" iyz="-7.5402e-05" izz="0.254469458"/>
    </inertial>
  </link>

  <link name="motorRL1">
    <visual>
      <origin rpy="0 0 0" xyz="0 0 0"/>
      <geometry>
	<box size="0.04 0.04 0.02"/>
      </geometry>
      <material name="silver"/>
    </visual>
    <collision>
      <origin rpy="0 0 0" xyz="0 0 0"/>
      <geometry>
	<box size="0.04 0.04 0.02"/>
      </geometry>
    </collision>
    <inertial>
      <origin rpy="0 0 0" xyz="0.002284 -4.1e-05 0.025165"/>
      <mass value="0.057"/>
      <inertia ixx="0.073348887" ixy="0.00030338" ixz="0.001918218" iyy="0.250684593" iyz="-7.5402e-05" izz="0.254469458"/>
    </inertial>
  </link>

  <link name="motorRR1">
    <visual>
      <origin rpy="0 0 0" xyz="0 0 0"/>
      <geometry>
	<box size="0.04 0.04 0.02"/>
      </geometry>
      <material name="silver"/>
    </visual>
    <collision>
      <origin rpy="0 0 0" xyz="0 0 0"/>
      <geometry>
	<box size="0.04 0.04 0.02"/>
      </geometry>
    </collision>
    <inertial>
      <origin rpy="0 0 0" xyz="0.002284 -4.1e-05 0.025165"/>
      <mass value="0.057"/>
      <inertia ixx="0.073348887" ixy="0.00030338" ixz="0.001918218" iyy="0.250684593" iyz="-7.5402e-05" izz="0.254469458"/>
    </inertial>
  </link>


  <joint name="chassis_motorFL" type="fixed">
    <parent link="chassis"/>
    <child link="motorFL1"/>
    <origin rpy="0 0 0" xyz="0.08 0.0305 -0.02"/>
    <axis xyz="0 0 0"/>
    <dynamics damping="0" friction="0"/>
    <limit effort="100" velocity="100"/>
  </joint>

  <joint name="chassis_motorFR" type="fixed">
    <parent link="chassis"/>
    <child link="motorFR1"/>
    <origin rpy="0 0 0" xyz="0.08 -0.0305 -0.02"/>
    <axis xyz="0 0 0"/>
    <dynamics damping="0" friction="0"/>
    <limit effort="100" velocity="100"/>
  </joint>

  <joint name="chassis_motorRL" type="fixed">
    <parent link="chassis"/>
    <child link="motorRL1"/>
    <origin rpy="0 0 0" xyz="-0.08 0.0305 -0.02"/>
    <axis xyz="0 0 0"/>
    <dynamics damping="0" friction="0"/>
    <limit effort="100" velocity="100"/>
  </joint>

  <joint name="chassis_motorRR" type="fixed">
    <parent link="chassis"/>
    <child link="motorRR1"/>
    <origin rpy="0 0 0" xyz="-0.08 -0.0305 -0.02"/>
    <axis xyz="0 0 0"/>
    <dynamics damping="0" friction="0"/>
    <limit effort="100" velocity="100"/>
  </joint>


  <link name="motorRL2">
    <visual>
      <origin rpy="0 0 0" xyz="0 0 0"/>
      <geometry>
	<box size="0.04 0.02 0.04"/>
      </geometry>
      <material name="silver"/>
    </visual>
    <collision>
      <origin rpy="0 0 0" xyz="0 0 0"/>
      <geometry>
	<box size="0.04 0.02 0.04"/>
      </geometry>
    </collision>
    <inertial>
      <origin rpy="0 0 0" xyz="0.002284 -4.1e-05 0.025165"/>
      <mass value="0.083"/>
      <inertia ixx="0.073348887" ixy="0.00030338" ixz="0.001918218" iyy="0.250684593" iyz="-7.5402e-05" izz="0.254469458"/>
    </inertial>
  </link>

  <link name="motorRR2">
    <visual>
      <origin rpy="0 0 0" xyz="0 0 0"/>
      <geometry>
	<box size="0.04 0.02 0.04"/>
      </geometry>
      <material name="silver"/>
    </visual>
    <collision>
      <origin rpy="0 0 0" xyz="0 0 0"/>
      <geometry>
	<box size="0.04 0.02 0.04"/>
      </geometry>
    </collision>
    <inertial>
      <origin rpy="0 0 0" xyz="0.002284 -4.1e-05 0.025165"/>
      <mass value="0.083"/>
      <inertia ixx="0.073348887" ixy="0.00030338" ixz="0.001918218" iyy="0.250684593" iyz="-7.5402e-05" izz="0.254469458"/>
    </inertial>
  </link>


  <joint name="motorRL1_motorRL2" type="revolute">
    <parent link="motorRL1"/>
    <child link="motorRL2"/>
    <origin rpy="0 0 0" xyz="-0.010 0.05 0"/> <!-- 0.04 + bracket distance -->
    <axis xyz="0 1 0"/>
    <dynamics damping="0" friction="0"/>
    <limit effort="100" lower="-3.14" upper="3.14" velocity="100"/>
  </joint>

  <joint name="motorRR1_motorRR2" type="revolute">
    <parent link="motorRR1"/>
    <child link="motorRR2"/>
    <origin rpy="0 0 0" xyz="-0.010 -0.05 0"/>
    <axis xyz="0 1 0"/>
    <dynamics damping="0" friction="0"/>
    <limit effort="100" lower="-3.14" upper="3.14" velocity="100"/>
  </joint>


  <link name="motorRL3">
    <visual>
      <origin rpy="0 0 0" xyz="0 0.01 0"/>
      <geometry>
	<box size="0.04 0.04 0.04"/>
      </geometry>
      <material name="silver"/>
    </visual>
    <collision>
      <origin rpy="0 0 0" xyz="0 0 0"/>
      <geometry>
	<box size="0.04 0.04 0.04"/>
      </geometry>
    </collision>
    <inertial>
      <origin rpy="0 0 0" xyz="0.002284 -4.1e-05 0.025165"/>
      <mass value="0.158"/>
      <inertia ixx="0.073348887" ixy="0.00030338" ixz="0.001918218" iyy="0.250684593" iyz="-7.5402e-05" izz="0.254469458"/>
    </inertial>
  </link>

  <link name="motorRR3">
    <visual>
      <origin rpy="0 0 0" xyz="0 -0.01 0"/>
      <geometry>
	<box size="0.04 0.04 0.04"/>
      </geometry>
      <material name="silver"/>
    </visual>
    <collision>
      <origin rpy="0 0 0" xyz="0 0 0"/>
      <geometry>
	<box size="0.04 0.04 0.04"/>
      </geometry>
    </collision>
    <inertial>
      <origin rpy="0 0 0" xyz="0.002284 -4.1e-05 0.025165"/>
      <mass value="0.158"/>
      <inertia ixx="0.073348887" ixy="0.00030338" ixz="0.001918218" iyy="0.250684593" iyz="-7.5402e-05" izz="0.254469458"/>
    </inertial>
  </link>


  <joint name="motorRL2_motorRL3" type="revolute">
    <parent link="motorRL2"/>
    <child link="motorRL3"/>
    <origin rpy="0 0 0" xyz="0.05 0 -0.01"/>
    <axis xyz="1 0 0"/>
    <dynamics damping="0" friction="0"/>
    <limit effort="100" lower="-3.14" upper="3.14" velocity="100"/>
  </joint>

  <joint name="motorRR2_motorRR3" type="revolute">
    <parent link="motorRR2"/>
    <child link="motorRR3"/>
    <origin rpy="0 0 0" xyz="0.05 0 -0.01"/>
    <axis xyz="1 0 0"/>
    <dynamics damping="0" friction="0"/>
    <limit effort="100" lower="-3.14" upper="3.14" velocity="100"/>
  </joint>


  <link name="motorFL2">
    <visual>
      <origin rpy="0 0 0" xyz="0 0.01 0"/>
      <geometry>
	<box size="0.04 0.04 0.04"/>
      </geometry>
      <material name="silver"/>
    </visual>
    <collision>
      <origin rpy="0 0 0" xyz="0 0 0"/>
      <geometry>
	<box size="0.04 0.04 0.04"/>
      </geometry>
    </collision>
    <inertial>
      <origin rpy="0 0 0" xyz="0.002284 -4.1e-05 0.025165"/>
      <mass value="0.158"/>
      <inertia ixx="0.073348887" ixy="0.00030338" ixz="0.001918218" iyy="0.250684593" iyz="-7.5402e-05" izz="0.254469458"/>
    </inertial>
  </link>

  <link name="motorFR2">
    <visual>
      <origin rpy="0 0 0" xyz="0 -0.01 0"/>
      <geometry>
	<box size="0.04 0.04 0.04"/>
      </geometry>
      <material name="silver"/>
    </visual>
    <collision>
      <origin rpy="0 0 0" xyz="0 0 0"/>
      <geometry>
	<box size="0.04 0.04 0.04"/>
      </geometry>
    </collision>
    <inertial>
      <origin rpy="0 0 0" xyz="0.002284 -4.1e-05 0.025165"/>
      <mass value="0.158"/>
      <inertia ixx="0.073348887" ixy="0.00030338" ixz="0.001918218" iyy="0.250684593" iyz="-7.5402e-05" izz="0.254469458"/>
    </inertial>
  </link>



  <joint name="motorFL1_motorFL2" type="revolute">
    <parent link="motorFL1"/>
    <child link="motorFL2"/>
    <origin rpy="0 0 0" xyz="0.05 0.01 0"/>
    <axis xyz="1 0 0"/>
    <dynamics damping="0" friction="0"/>
    <limit effort="100" lower="-3.14" upper="3.14" velocity="100"/>
  </joint>
  <joint name="motorFR1_motorFR2" type="revolute">
    <parent link="motorFR1"/>
    <child link="motorFR2"/>
    <origin rpy="0 0 0" xyz="0.05 -0.01 0"/>
    <axis xyz="1 0 0"/>
    <dynamics damping="0" friction="0"/>
    <limit effort="100" lower="-3.14" upper="3.14" velocity="100"/>
  </joint>





  <link name="FL_thigh">
    <visual>
      <origin rpy="0 0 0" xyz="-0.03 0 0"/>
      <geometry>
	<!--<mesh filename="package://stuart_urdf/meshes/thigh.dae"/>-->
        <box size="0.07 0.005 0.01"/>
      </geometry>
      <material name="silver"/>
    </visual>
    <collision>
      <origin rpy="0 0 0" xyz="0 0 0"/>
      <geometry>
	<box size="0.04 0.04 0.04"/>
      </geometry>
    </collision>
    <inertial>
      <origin rpy="0 0 0" xyz="0.002284 -4.1e-05 0.025165"/>
      <mass value="0.0033"/>
      <inertia ixx="0.073348887" ixy="0.00030338" ixz="0.001918218" iyy="0.250684593" iyz="-7.5402e-05" izz="0.254469458"/>
    </inertial>
  </link>

  <link name="FR_thigh">
    <visual>
      <origin rpy="0 0 0" xyz="-0.03 0 0"/>
      <geometry>
	<!--<mesh filename="package://stuart_urdf/meshes/thigh.dae"/>-->
        <box size="0.07 0.005 0.01"/>
      </geometry>
      <material name="silver"/>
    </visual>
    <collision>
      <origin rpy="0 0 0" xyz="0 0 0"/>
      <geometry>
	<box size="0.04 0.04 0.04"/>
      </geometry>
    </collision>
    <inertial>
      <origin rpy="0 0 0" xyz="0.002284 -4.1e-05 0.025165"/>
      <mass value="0.0033"/>
      <inertia ixx="0.073348887" ixy="0.00030338" ixz="0.001918218" iyy="0.250684593" iyz="-7.5402e-05" izz="0.254469458"/>
    </inertial>
  </link>

  <link name="RL_thigh">
    <visual>
      <origin rpy="0 0 0" xyz="-0.03 0 0"/>
      <geometry>
	<!--<mesh filename="package://stuart_urdf/meshes/thigh.dae"/>-->
        <box size="0.07 0.005 0.01"/>
      </geometry>
      <material name="silver"/>
    </visual>
    <collision>
      <origin rpy="0 0 0" xyz="0 0 0"/>
      <geometry>
	<box size="0.04 0.04 0.04"/>
      </geometry>
    </collision>
    <inertial>
      <origin rpy="0 0 0" xyz="0.002284 -4.1e-05 0.025165"/>
      <mass value="0.0033"/>
      <inertia ixx="0.073348887" ixy="0.00030338" ixz="0.001918218" iyy="0.250684593" iyz="-7.5402e-05" izz="0.254469458"/>
    </inertial>
  </link>

  <link name="RR_thigh">
    <visual>
      <origin rpy="0 0 0" xyz="-0.03 0 0"/>
      <geometry>
	<!--<mesh filename="package://stuart_urdf/meshes/thigh.dae"/>-->
        <box size="0.07 0.005 0.01"/>
      </geometry>
      <material name="silver"/>
    </visual>
    <collision>
      <origin rpy="0 0 0" xyz="0 0 0"/>
      <geometry>
	<box size="0.04 0.04 0.04"/>
      </geometry>
    </collision>
    <inertial>
      <origin rpy="0 0 0" xyz="0.002284 -4.1e-05 0.025165"/>
      <mass value="0.0033"/>
      <inertia ixx="0.073348887" ixy="0.00030338" ixz="0.001918218" iyy="0.250684593" iyz="-7.5402e-05" izz="0.254469458"/>
    </inertial>
  </link>

  <joint name="motorFL2_thigh" type="revolute">
    <parent link="motorFL2"/>
    <child link="FL_thigh"/>
    <origin rpy="0 0 0" xyz="-0.01 0.0375 -0.01"/>
    <axis xyz="0 1 0"/>
    <dynamics damping="0" friction="0"/>
    <limit effort="100" lower="-3.14" upper="3.14" velocity="100"/>
  </joint>
  <joint name="motorFR2_thigh" type="revolute">
    <parent link="motorFR2"/>
    <child link="FR_thigh"/>
    <origin rpy="0 0 0" xyz="-0.01 -0.0375 -0.01"/>
    <axis xyz="0 1 0"/>
    <dynamics damping="0" friction="0"/>
    <limit effort="100" lower="-3.14" upper="3.14" velocity="100"/>
  </joint>


  <joint name="motorRL3_thigh" type="revolute">
    <parent link="motorRL3"/>
    <child link="RL_thigh"/>
    <origin rpy="0 0 0" xyz="-0.01 0.0375 -0.01"/>
    <axis xyz="0 1 0"/>
    <dynamics damping="0" friction="0"/>
    <limit effort="100" lower="-3.14" upper="3.14" velocity="100"/>
  </joint>
  <joint name="motorRR3_thigh" type="revolute">
    <parent link="motorRR3"/>
    <child link="RR_thigh"/>
    <origin rpy="0 0 0" xyz="-0.01 -0.0375 -0.01"/>
    <axis xyz="0 1 0"/>
    <dynamics damping="0" friction="0"/>
    <limit effort="100" lower="-3.14" upper="3.14" velocity="100"/>
  </joint>

  <link name="FL_calf">
    <visual>
      <origin rpy="0 0 0" xyz="-0.035 0 0"/>
      <geometry>
	<!--<mesh filename="package://stuart_urdf/meshes/thigh.dae"/>-->
        <box size="0.08 0.005 0.01"/>
      </geometry>
      <material name="silver"/>
    </visual>
    <collision>
      <origin rpy="0 0 0" xyz="0 0 0"/>
      <geometry>
	<box size="0.04 0.04 0.04"/>
      </geometry>
    </collision>
    <inertial>
      <origin rpy="0 0 0" xyz="0.002284 -4.1e-05 0.025165"/>
      <mass value="0.00379"/>
      <inertia ixx="0.073348887" ixy="0.00030338" ixz="0.001918218" iyy="0.250684593" iyz="-7.5402e-05" izz="0.254469458"/>
    </inertial>
  </link>

  <link name="FR_calf">
    <visual>
      <origin rpy="0 0 0" xyz="-0.035 0 0"/>
      <geometry>
	<!--<mesh filename="package://stuart_urdf/meshes/thigh.dae"/>-->
        <box size="0.08 0.005 0.01"/>
      </geometry>
      <material name="silver"/>
    </visual>
    <collision>
      <origin rpy="0 0 0" xyz="0 0 0"/>
      <geometry>
	<box size="0.04 0.04 0.04"/>
      </geometry>
    </collision>
    <inertial>
      <origin rpy="0 0 0" xyz="0.002284 -4.1e-05 0.025165"/>
      <mass value="0.00379"/>
      <inertia ixx="0.073348887" ixy="0.00030338" ixz="0.001918218" iyy="0.250684593" iyz="-7.5402e-05" izz="0.254469458"/>
    </inertial>
  </link>

  <link name="RL_calf">
    <visual>
      <origin rpy="0 0 0" xyz="-0.035 0 0"/>
      <geometry>
	<!--<mesh filename="package://stuart_urdf/meshes/thigh.dae"/>-->
        <box size="0.08 0.005 0.01"/>
      </geometry>
      <material name="silver"/>
    </visual>
    <collision>
      <origin rpy="0 0 0" xyz="0 0 0"/>
      <geometry>
	<box size="0.04 0.04 0.04"/>
      </geometry>
    </collision>
    <inertial>
      <origin rpy="0 0 0" xyz="0.002284 -4.1e-05 0.025165"/>
      <mass value="0.00379"/>
      <inertia ixx="0.073348887" ixy="0.00030338" ixz="0.001918218" iyy="0.250684593" iyz="-7.5402e-05" izz="0.254469458"/>
    </inertial>
  </link>

  <link name="RR_calf">
    <visual>
      <origin rpy="0 0 0" xyz="-0.035 0 0"/>
      <geometry>
	<!--<mesh filename="package://stuart_urdf/meshes/thigh.dae"/>-->
        <box size="0.08 0.005 0.01"/>
      </geometry>
      <material name="silver"/>
    </visual>
    <collision>
      <origin rpy="0 0 0" xyz="0 0 0"/>
      <geometry>
	<box size="0.04 0.04 0.04"/>
      </geometry>
    </collision>
    <inertial>
      <origin rpy="0 0 0" xyz="0.002284 -4.1e-05 0.025165"/>
      <mass value="0.00379"/>
      <inertia ixx="0.073348887" ixy="0.00030338" ixz="0.001918218" iyy="0.250684593" iyz="-7.5402e-05" izz="0.254469458"/>
    </inertial>
  </link>

  <joint name="FLthigh_calf" type="revolute">
    <parent link="FL_thigh"/>
    <child link="FL_calf"/>
    <origin rpy="0 0 0" xyz="-0.060 0.005 0"/>
    <axis xyz="0 1 0"/>
    <dynamics damping="0" friction="0"/>
    <limit effort="100" lower="-3.14" upper="3.14" velocity="100"/>
  </joint>
  <joint name="FRthigh_calf" type="revolute">
    <parent link="FR_thigh"/>
    <child link="FR_calf"/>
    <origin rpy="0 0 0" xyz="-0.060 -0.005 0"/>
    <axis xyz="0 1 0"/>
    <dynamics damping="0" friction="0"/>
    <limit effort="100" lower="-3.14" upper="3.14" velocity="100"/>
  </joint>
  <joint name="RLthigh_calf" type="revolute">
    <parent link="RL_thigh"/>
    <child link="RL_calf"/>
    <origin rpy="0 0 0" xyz="-0.060 0.005 0"/>
    <axis xyz="0 1 0"/>
    <dynamics damping="0" friction="0"/>
    <limit effort="100" lower="-3.14" upper="3.14" velocity="100"/>
  </joint>
  <joint name="RRthigh_calf" type="revolute">
    <parent link="RR_thigh"/>
    <child link="RR_calf"/>
    <origin rpy="0 0 0" xyz="-0.060 -0.005 0"/>
    <axis xyz="0 1 0"/>
    <dynamics damping="0" friction="0"/>
    <limit effort="100" lower="-3.14" upper="3.14" velocity="100"/>
  </joint>

  <link name="FL_foot">
    <visual>
      <origin rpy="0 0 0" xyz="-0.0025 0 0"/>
      <geometry>
	<!--<mesh filename="package://stuart_urdf/meshes/foot.dae"/>-->
	<box size="0.015 0.02 0.04"/>
      </geometry>
      <material name="silver"/>
    </visual>
    <collision>
      <origin rpy="0 0 0" xyz="0 0 0"/>
      <geometry>
	<box size="0.015 0.02 0.04"/>
      </geometry>
      <surface>
        <friction>
          <ode>
            <mu>10000.0</mu>
            <mu2>10000.0</mu2>
          </ode>
        </friction>
      </surface>
    </collision>
    <inertial>
      <origin rpy="0 0 0" xyz="0.002284 -4.1e-05 0.025165"/>
      <mass value="0.00566"/>
      <inertia ixx="0.073348887" ixy="0.00030338" ixz="0.001918218" iyy="0.250684593" iyz="-7.5402e-05" izz="0.254469458"/>
    </inertial>
  </link>

  <link name="FR_foot">
    <visual>
      <origin rpy="0 0 0" xyz="-0.0025 0 0"/>
      <geometry>
	<!--<mesh filename="package://stuart_urdf/meshes/foot.dae"/>-->
	<box size="0.015 0.02 0.04"/>
      </geometry>
      <material name="silver"/>
    </visual>
    <collision>
      <origin rpy="0 0 0" xyz="0 0 0"/>
      <geometry>
	<box size="0.015 0.02 0.04"/>
      </geometry>
      <surface>
        <friction>
          <ode>
            <mu>10000.0</mu>
            <mu2>10000.0</mu2>
          </ode>
        </friction>
      </surface>
    </collision>
    <inertial>
      <origin rpy="0 0 0" xyz="0.002284 -4.1e-05 0.025165"/>
      <mass value="0.00566"/>
      <inertia ixx="0.073348887" ixy="0.00030338" ixz="0.001918218" iyy="0.250684593" iyz="-7.5402e-05" izz="0.254469458"/>
    </inertial>
  </link>

  <link name="RL_foot">
    <visual>
      <origin rpy="0 0 0" xyz="-0.0025 0 0"/>
      <geometry>
	<!--<mesh filename="package://stuart_urdf/meshes/foot.dae"/>-->
	<box size="0.015 0.02 0.04"/>
      </geometry>
      <material name="silver"/>
    </visual>
    <collision>
      <origin rpy="0 0 0" xyz="0 0 0"/>
      <geometry>
	<box size="0.015 0.02 0.04"/>
      </geometry>
      <surface>
        <friction>
          <ode>
            <mu>10000.0</mu>
            <mu2>10000.0</mu2>
          </ode>
        </friction>
      </surface>
    </collision>
    <inertial>
      <origin rpy="0 0 0" xyz="0.002284 -4.1e-05 0.025165"/>
      <mass value="0.00566"/>
      <inertia ixx="0.073348887" ixy="0.00030338" ixz="0.001918218" iyy="0.250684593" iyz="-7.5402e-05" izz="0.254469458"/>
    </inertial>
  </link>

  <link name="RR_foot">
    <visual>
      <origin rpy="0 0 0" xyz="-0.0025 0 0"/>
      <geometry>
	<!--<mesh filename="package://stuart_urdf/meshes/foot.dae"/>-->
	<box size="0.015 0.02 0.04"/>
      </geometry>
      <material name="silver"/>
    </visual>
    <collision>
      <origin rpy="0 0 0" xyz="0 0 0"/>
      <geometry>
	<box size="0.015 0.02 0.04"/>
      </geometry>
      <surface>
        <friction>
          <ode>
            <mu>10000.0</mu>
            <mu2>10000.0</mu2>
          </ode>
        </friction>
      </surface>
    </collision>
    <inertial>
      <origin rpy="0 0 0" xyz="0.002284 -4.1e-05 0.025165"/>
      <mass value="0.00566"/>
      <inertia ixx="0.073348887" ixy="0.00030338" ixz="0.001918218" iyy="0.250684593" iyz="-7.5402e-05" izz="0.254469458"/>
    </inertial>
  </link>


  <joint name="FLcalf_foot" type="continuous">
    <parent link="FL_calf"/>
    <child link="FL_foot"/>
    <origin rpy="0 0 0" xyz="-0.07 0 0"/>
    <axis xyz="0 1 0"/>
    <dynamics damping="0" friction="0"/>
    <limit effort="0" velocity="100"/>
  </joint>
  <joint name="FRcalf_foot" type="continuous">
    <parent link="FR_calf"/>
    <child link="FR_foot"/>
    <origin rpy="0 0 0" xyz="-0.07 0 0"/>
    <axis xyz="0 1 0"/>
    <dynamics damping="0" friction="0"/>
    <limit effort="0" velocity="100"/>
  </joint>
  <joint name="RLcalf_foot" type="continuous">
    <parent link="RL_calf"/>
    <child link="RL_foot"/>
    <origin rpy="0 0 0" xyz="-0.07 0 0"/>
    <axis xyz="0 1 0"/>
    <dynamics damping="0" friction="0"/>
    <limit effort="0" velocity="100"/>
  </joint>
  <joint name="RRcalf_foot" type="continuous">
    <parent link="RR_calf"/>
    <child link="RR_foot"/>
    <origin rpy="0 0 0" xyz="-0.07 0 0"/>
    <axis xyz="0 1 0"/>
    <dynamics damping="0" friction="0"/>
    <limit effort="0" velocity="100"/>
  </joint>











  <link name="imu_link">
    <inertial>
      <mass value="0.01"/>
      <origin xyz="0 0 0"/>
      <inertia ixx="0.000001" ixy="0" ixz="0" iyy="0.000001" iyz="0" izz="0.000001"/>
    </inertial>
    <visual>
      <origin rpy="0 0 0" xyz="0 0 0"/>
      <geometry>
        <box size="0.01 0.01 0.01"/>
      </geometry>
    </visual>
  </link>
  <joint name="imu_joint" type="fixed">
    <origin rpy="3.14159265359 0 0" xyz="0 0 0"/>
    <parent link="chassis"/>
    <child link="imu_link"/>
  </joint>

  <gazebo reference="imu_link">
    <sensor name="imu_link" type="imu">
      <always_on>1</always_on>
      <update_rate>500</update_rate>
      <visualize>true</visualize>
      <topic>__default_topic__</topic>
      <imu>

      </imu>
    </sensor>
  </gazebo>
  <gazebo>
    <plugin filename="libGazeboXBotPlugin.so" name="xbot_plugin_handler">
      <path_to_config_file>configs/stuart/configs/stuart.yaml</path_to_config_file>
    </plugin>
  </gazebo>
  <origin rpy="0 0 0" xyz="0.0 0.0 0.20"/>
</robot>

