<?xml version="1.0" ?>

<robot name="stuart" xmlns:xacro="http://wiki.ros.org/xacro">

  <material name="grey">
    <color rgba="0.5 0.5 0.5 1"/>
  </material>
  <material name="dark_grey">
    <color rgba="0.3 0.3 0.3 1"/>
  </material>
  <material name="red">
    <color rgba="1.0 0.0 0.0 1"/>
  </material>
  <material name="green">
    <color rgba="0.0 1.0 0.0 1"/>
  </material>
  <material name="black">
    <color rgba="0.1 0.1 0.1 1"/>
  </material>
  <material name="light_grey">
    <color rgba="0.8 0.8 0.8 1"/>
  </material>
  <material name="blue">
    <color rgba="0.0 0.0 0.8 1.0"/>
  </material>
  <material name="silver">
    <color rgba="0.913725490196 0.913725490196 0.847058823529 1.0"/>
  </material>
  <material name="orange">
    <color rgba="1.0 0.423529411765 0.0392156862745 1.0"/>
  </material>
  <material name="brown">
    <color rgba="0.870588235294 0.811764705882 0.764705882353 1.0"/>
  </material>
  <material name="white">
    <color rgba="1.0 1.0 1.0 1.0"/>
  </material>

  <link name="world"/>
   <joint name="reference" type="fixed">
     <origin xyz="0.0 0.0 0.5"/>
     <parent link="world"/>
     <child link="chassis"/>
   </joint>

  <link name="chassis">
    <visual>
      <origin rpy="0 0 0" xyz="0 0 0"/>
      <geometry>
        <mesh filename="package://stuart_urdf/meshes/chassis2.stl" scale="0.001 0.001 0.001"/>
      </geometry>
      <material name="silver"/>
    </visual>
    <collision>
      <origin rpy="0 0 0" xyz="0 0 0"/>
      <geometry>
        <box size="0.2 0.105 0.01"/>
      </geometry>
    </collision>
    <inertial>
      <origin rpy="0 0 0" xyz="0 0 0"/>
      <mass value="0.652"/>
      <inertia ixx="4284003.36" ixy="683684.97" ixz="168.40" iyy="852840.69" iyz="195.18" izz="2176900.67"/>
    </inertial>
  </link>

  <link name="motorFL1">
    <visual>
      <origin rpy="0 0 0" xyz="0 0 0"/>
      <geometry>
	<mesh filename="package://stuart_urdf/meshes/frontleftrollmotor.stl" scale="0.001 0.001 0.001"/>
      </geometry>
      <material name="silver"/>
    </visual>
    <collision>
      <origin rpy="0 0 0" xyz="0 0 0"/>
      <geometry>
	<box size="0.04 0.04 0.02"/>
      </geometry>
    </collision>
    <inertial>
      <origin rpy="0 0 0" xyz="0 0 0"/>
      <mass value="0.069"/>
      <inertia ixx="14153.08" ixy="23.16" ixz="17.39" iyy="19823.76" iyz="1.78" izz="12751.31"/>
    </inertial>
  </link>

  <link name="motorFR1">
    <visual>
      <origin rpy="0 0 0" xyz="0 0 0"/>
      <geometry>
	<mesh filename="package://stuart_urdf/meshes/frontrightrollmotor.stl" scale="0.001 0.001 0.001"/>
      </geometry>
      <material name="silver"/>
    </visual>
    <collision>
      <origin rpy="0 0 0" xyz="0 0 0"/>
      <geometry>
	<box size="0.04 0.04 0.02"/>
      </geometry>
    </collision>
    <inertial>
      <origin rpy="0 0 0" xyz="0 0 0"/>
      <mass value="0.069"/>
      <inertia ixx="14153.08" ixy="23.16" ixz="17.39" iyy="19823.76" iyz="1.78" izz="12751.31"/>
    </inertial>
  </link>

  <link name="motorRL1">
    <visual>
      <origin rpy="0 0 0" xyz="0 0 0"/>
      <geometry>
	<mesh filename="package://stuart_urdf/meshes/rearlefthipmotor.stl" scale="0.001 0.001 0.001"/>
      </geometry>
      <material name="silver"/>
    </visual>
    <collision>
      <origin rpy="0 0 0" xyz="0 0 0"/>
      <geometry>
	<box size="0.04 0.04 0.02"/>
      </geometry>
    </collision>
    <inertial>
      <origin rpy="0 0 0" xyz="0 0 0"/>
      <mass value="0.069"/>
      <inertia ixx="14153.08" ixy="23.16" ixz="17.39" iyy="19823.76" iyz="1.78" izz="12751.31"/>
    </inertial>
  </link>

  <link name="motorRR1">
    <visual>
      <origin rpy="0 0 0" xyz="0 0 0"/>
      <geometry>
	<mesh filename="package://stuart_urdf/meshes/rearrighthipmotor.stl" scale="0.001 0.001 0.001"/>
      </geometry>
      <material name="silver"/>
    </visual>
    <collision>
      <origin rpy="0 0 0" xyz="0 0 0"/>
      <geometry>
	<box size="0.04 0.04 0.02"/>
      </geometry>
    </collision>
    <inertial>
      <origin rpy="0 0 0" xyz="0 0 0"/>
      <mass value="0.069"/>
      <inertia ixx="14153.08" ixy="23.16" ixz="17.39" iyy="19823.76" iyz="1.78" izz="12751.31"/>
    </inertial>
  </link>

  <joint name="chassis_motorFL" type="fixed">
    <parent link="chassis"/>
    <child link="motorFL1"/>
    <origin rpy="0 0 0" xyz="0.0808 0.0388 -0.0203"/>
    <axis xyz="0 0 0"/>
    <dynamics damping="0" friction="0"/>
    <limit effort="100" velocity="100"/>
  </joint>
  <joint name="chassis_motorFR" type="fixed">
    <parent link="chassis"/>
    <child link="motorFR1"/>
    <origin rpy="0 0 0" xyz="0.0808 -0.0388 -0.0203"/>
    <axis xyz="0 0 0"/>
    <dynamics damping="0" friction="0"/>
    <limit effort="100" velocity="100"/>
  </joint>
  <joint name="chassis_motorRL" type="fixed">
    <parent link="chassis"/>
    <child link="motorRL1"/>
    <origin rpy="0 0 0" xyz="-0.0792 0.0308 -0.0203"/>
    <axis xyz="0 0 0"/>
    <dynamics damping="0" friction="0"/>
    <limit effort="100" velocity="100"/>
  </joint>
  <joint name="chassis_motorRR" type="fixed">
    <parent link="chassis"/>
    <child link="motorRR1"/>
    <origin rpy="0 0 0" xyz="-0.0792 -0.0308 -0.0203"/>
    <axis xyz="0 0 0"/>
    <dynamics damping="0" friction="0"/>
    <limit effort="100" velocity="100"/>
  </joint>

  <link name="motorRL2">
    <visual>
      <origin rpy="0 0 0" xyz="-0.0015 0 -0.006"/>
      <geometry>
	<mesh filename="package://stuart_urdf/meshes/rearleftrollmotor.stl" scale="0.001 0.001 0.001"/>
      </geometry>
      <material name="silver"/>
    </visual>
    <collision>
      <origin rpy="0 0 0" xyz="-0.0015 0 -0.006"/>
      <geometry>
	<box size="0.04 0.02 0.04"/>
      </geometry>
    </collision>
    <inertial>
      <origin rpy="0 0 0" xyz="0 0 0"/>
      <mass value="0.083"/>
      <inertia ixx="41991.04" ixy="41.45" ixz="203.55" iyy="41434.81" iyz="4644.49" izz="22667.59"/>
    </inertial>
  </link>

  <link name="motorRR2">
    <visual>
      <origin rpy="0 0 0" xyz="-0.0015 0 -0.006"/>
      <geometry>
	<mesh filename="package://stuart_urdf/meshes/rearrightrollmotor.stl" scale="0.001 0.001 0.001"/>
      </geometry>
      <material name="silver"/>
    </visual>
    <collision>
      <origin rpy="0 0 0" xyz="-0.0015 0 -0.006"/>
      <geometry>
	<box size="0.04 0.02 0.04"/>
      </geometry>
    </collision>
    <inertial>
      <origin rpy="0 0 0" xyz="0 0 0"/>
      <mass value="0.083"/>
      <inertia ixx="41991.04" ixy="41.45" ixz="203.55" iyy="41434.81" iyz="4644.49" izz="22667.59"/>
    </inertial>
  </link>

  <joint name="motorRL1_motorRL2" type="revolute">
    <parent link="motorRL1"/>
    <child link="motorRL2"/>
    <origin rpy="0 0 0" xyz="-0.0035 0.035 -0.002"/> <!-- 0.04 + bracket distance -->
    <axis xyz="0 1 0"/>
    <dynamics damping="0" friction="0"/>
    <limit effort="100" lower="-3.14" upper="3.14" velocity="100"/>
  </joint>
  <joint name="motorRR1_motorRR2" type="revolute">
    <parent link="motorRR1"/>
    <child link="motorRR2"/>
    <origin rpy="0 0 0" xyz="-0.0035 -0.035 -0.002"/>
    <axis xyz="0 1 0"/>
    <dynamics damping="0" friction="0"/>
    <limit effort="100" lower="-3.14" upper="3.14" velocity="100"/>
  </joint>



  <link name="motorRL3">
    <visual>
      <origin rpy="0 0 0" xyz="0 0.012 -0.0025"/>
      <geometry>
	<mesh filename="package://stuart_urdf/meshes/rearleftpitchmotor.stl" scale="0.001 0.001 0.001"/>
      </geometry>
      <material name="silver"/>
    </visual>
    <collision>
      <origin rpy="0 0 0" xyz="0 0.012 -0.0025"/>
      <geometry>
	<box size="0.04 0.04 0.04"/>
      </geometry>
    </collision>
    <inertial>
      <origin rpy="0 0 0" xyz="0 0 0"/>
      <mass value="0.145"/>
      <inertia ixx="42568.51" ixy="-1940.57" ixz="2349.84" iyy="83104.88" iyz="-214.67" izz="83850.40"/>
    </inertial>
  </link>

  <link name="motorRR3">
    <visual>
      <origin rpy="0 0 0" xyz="0 -0.012 -0.0025"/>
      <geometry>
	<mesh filename="package://stuart_urdf/meshes/rearrightpitchmotor.stl" scale="0.001 0.001 0.001"/>
      </geometry>
      <material name="silver"/>
    </visual>
    <collision>
      <origin rpy="0 0 0" xyz="0 -0.012 -0.0025"/>
      <geometry>
	<box size="0.04 0.04 0.04"/>
      </geometry>
    </collision>
    <inertial>
      <origin rpy="0 0 0" xyz="0 0 0"/>
      <mass value="0.145"/>
      <inertia ixx="42568.51" ixy="-1940.57" ixz="2349.84" iyy="83104.88" iyz="-214.67" izz="83850.40"/>
    </inertial>
  </link>

  <joint name="motorRL2_motorRL3" type="revolute">
    <parent link="motorRL2"/>
    <child link="motorRL3"/>
    <origin rpy="0 0 0" xyz="0.038 0.0095 -0.01055"/>
    <axis xyz="1 0 0"/>
    <dynamics damping="0" friction="0"/>
    <limit effort="100" lower="-3.14" upper="3.14" velocity="100"/>
  </joint>
  <joint name="motorRR2_motorRR3" type="revolute">
    <parent link="motorRR2"/>
    <child link="motorRR3"/>
    <origin rpy="0 0 0" xyz="0.038 -0.0095 -0.01055"/>
    <axis xyz="1 0 0"/>
    <dynamics damping="0" friction="0"/>
    <limit effort="100" lower="-3.14" upper="3.14" velocity="100"/>
  </joint>


 <link name="motorFL2">
    <visual>
      <origin rpy="0 0 0" xyz="0 0.0122 -0.0023"/>
      <geometry>
	<mesh filename="package://stuart_urdf/meshes/frontleftpitchmotor.stl" scale="0.001 0.001 0.001"/>
      </geometry>
      <material name="silver"/>
    </visual>
    <collision>
      <origin rpy="0 0 0" xyz="0 0.0122 -0.0023"/>
      <geometry>
	<box size="0.04 0.04 0.04"/>
      </geometry>
    </collision>
    <inertial>
      <origin rpy="0 0 0" xyz="0 0 0"/>
      <mass value="0.145"/>
      <inertia ixx="42568.51" ixy="-1940.57" ixz="2349.84" iyy="83104.88" iyz="-214.67" izz="83850.40"/>
    </inertial>
  </link>

  <link name="motorFR2">
    <visual>
      <origin rpy="0 0 0" xyz="0 -0.0122 -0.0023"/>
      <geometry>
	<mesh filename="package://stuart_urdf/meshes/frontrightpitchmotor.stl" scale="0.001 0.001 0.001"/>
      </geometry>
      <material name="silver"/>
    </visual>
    <collision>
      <origin rpy="0 0 0" xyz="0 -0.0122 -0.0023"/>
      <geometry>
	<box size="0.04 0.04 0.04"/>
      </geometry>
    </collision>
    <inertial>
      <origin rpy="0 0 0" xyz="0 0 0"/>
      <mass value="0.145"/>
      <inertia ixx="42568.51" ixy="-1940.57" ixz="2349.84" iyy="83104.88" iyz="-214.67" izz="83850.40"/>
    </inertial>
  </link>

  <joint name="motorFL1_motorFL2" type="revolute">
    <parent link="motorFL1"/>
    <child link="motorFL2"/>
    <origin rpy="0 0 0" xyz="0.04 0.0034 -0.0021"/>
    <axis xyz="1 0 0"/>
    <dynamics damping="0" friction="0"/>
    <limit effort="100" lower="-3.14" upper="3.14" velocity="100"/>
  </joint>
  <joint name="motorFR1_motorFR2" type="revolute">
    <parent link="motorFR1"/>
    <child link="motorFR2"/>
    <origin rpy="0 0 0" xyz="0.04 -0.0034 -0.0021"/>
    <axis xyz="1 0 0"/>
    <dynamics damping="0" friction="0"/>
    <limit effort="100" lower="-3.14" upper="3.14" velocity="100"/>
  </joint>

<link name="FL_thigh">
    <visual>
      <origin rpy="0 0 0" xyz="-0.0365 0 0"/>
      <geometry>
	<mesh filename="package://stuart_urdf/meshes/thighlink.stl" scale="0.001 0.001 0.001"/>
      </geometry>
      <material name="silver"/>
    </visual>
    <collision>
      <origin rpy="0 0 0" xyz="-0.0365 0 0"/>
      <geometry>
	<box size="0.04 0.04 0.04"/>
      </geometry>
    </collision>
    <inertial>
      <origin rpy="0 0 0" xyz="0 0 0"/>
      <mass value="0.0033"/>
      <inertia ixx="394.51" ixy="549.97" ixz="14.31" iyy="876.41" iyz="9.85" izz="1256.66"/>
    </inertial>
  </link>

  <link name="FR_thigh">
    <visual>
      <origin rpy="0 0 0" xyz="-0.0365 0 0"/>
      <geometry>
	<mesh filename="package://stuart_urdf/meshes/thighlink.stl" scale="0.001 0.001 0.001"/>
      </geometry>
      <material name="silver"/>
    </visual>
    <collision>
      <origin rpy="0 0 0" xyz="-0.0365 0 0"/>
      <geometry>
	<box size="0.04 0.04 0.04"/>
      </geometry>
    </collision>
    <inertial>
      <origin rpy="0 0 0" xyz="0 0 0"/>
      <mass value="0.0033"/>
      <inertia ixx="394.51" ixy="549.97" ixz="14.31" iyy="876.41" iyz="9.85" izz="1256.66"/>
    </inertial>
  </link>

  <link name="RL_thigh">
    <visual>
      <origin rpy="0 0 0" xyz="-0.0365 0 0"/>
      <geometry>
	<mesh filename="package://stuart_urdf/meshes/thighlink.stl" scale="0.001 0.001 0.001"/>
      </geometry>
      <material name="silver"/>
    </visual>
    <collision>
      <origin rpy="0 0 0" xyz="-0.0365 0 0"/>
      <geometry>
	<box size="0.04 0.04 0.04"/>
      </geometry>
    </collision>
    <inertial>
      <origin rpy="0 0 0" xyz="0 0 0"/>
      <mass value="0.0033"/>
      <inertia ixx="394.51" ixy="549.97" ixz="14.31" iyy="876.41" iyz="9.85" izz="1256.66"/>
    </inertial>
  </link>

  <link name="RR_thigh">
    <visual>
      <origin rpy="0 0 0" xyz="-0.0365 0 0"/>
      <geometry>
	<mesh filename="package://stuart_urdf/meshes/thighlink.stl" scale="0.001 0.001 0.001"/>
      </geometry>
      <material name="silver"/>
    </visual>
    <collision>
      <origin rpy="0 0 0" xyz="-0.0365 0 0"/>
      <geometry>
	<box size="0.04 0.04 0.04"/>
      </geometry>
    </collision>
    <inertial>
      <origin rpy="0 0 0" xyz="0 0 0"/>
      <mass value="0.0033"/>
      <inertia ixx="394.51" ixy="549.97" ixz="14.31" iyy="876.41" iyz="9.85" izz="1256.66"/>
    </inertial>
  </link>

  <joint name="motorFL2_thigh" type="revolute">
    <parent link="motorFL2"/>
    <child link="FL_thigh"/>
    <origin rpy="0 0 0" xyz="0.005 0.039 -0.01"/>
    <axis xyz="0 1 0"/>
    <dynamics damping="0" friction="0"/>
    <limit effort="100" lower="-3.14" upper="3.14" velocity="100"/>
  </joint>
  <joint name="motorFR2_thigh" type="revolute">
    <parent link="motorFR2"/>
    <child link="FR_thigh"/>
    <origin rpy="0 0 0" xyz="0.005 -0.039 -0.01"/>
    <axis xyz="0 1 0"/>
    <dynamics damping="0" friction="0"/>
    <limit effort="100" lower="-3.14" upper="3.14" velocity="100"/>
  </joint>


  <joint name="motorRL3_thigh" type="revolute">
    <parent link="motorRL3"/>
    <child link="RL_thigh"/>
    <origin rpy="0 0 0" xyz="0.005 0.039 -0.01"/>
    <axis xyz="0 1 0"/>
    <dynamics damping="0" friction="0"/>
    <limit effort="100" lower="-3.14" upper="3.14" velocity="100"/>
  </joint>
  <joint name="motorRR3_thigh" type="revolute">
    <parent link="motorRR3"/>
    <child link="RR_thigh"/>
    <origin rpy="0 0 0" xyz="0.005 -0.039 -0.01"/>
    <axis xyz="0 1 0"/>
    <dynamics damping="0" friction="0"/>
    <limit effort="100" lower="-3.14" upper="3.14" velocity="100"/>
  </joint>


  <link name="FL_calf">
    <visual>
      <origin rpy="0 0 0" xyz="-0.036 0 0"/>
      <geometry>
	<mesh filename="package://stuart_urdf/meshes/calflink.stl" scale="0.001 0.001 0.001"/>
      </geometry>
      <material name="silver"/>
    </visual>
    <collision>
      <origin rpy="0 0 0" xyz="-0.036 0 0"/>
      <geometry>
	<box size="0.04 0.04 0.04"/>
      </geometry>
    </collision>
    <inertial>
      <origin rpy="0 0 0" xyz="0 0 0"/>
      <mass value="0.00379"/>
      <inertia ixx="1454.94" ixy="-784.08" ixz="-18.54" iyy="475.55" iyz="34.08" izz="1913.10"/>
    </inertial>
  </link>

  <link name="FR_calf">
    <visual>
      <origin rpy="0 0 0" xyz="-0.036 0 0"/>
      <geometry>
	<mesh filename="package://stuart_urdf/meshes/calflink.stl" scale="0.001 0.001 0.001"/>
      </geometry>
      <material name="silver"/>
    </visual>
    <collision>
      <origin rpy="0 0 0" xyz="-0.036 0 0"/>
      <geometry>
	<box size="0.04 0.04 0.04"/>
      </geometry>
    </collision>
    <inertial>
      <origin rpy="0 0 0" xyz="0 0 0"/>
      <mass value="0.00379"/>
      <inertia ixx="1454.94" ixy="-784.08" ixz="-18.54" iyy="475.55" iyz="34.08" izz="1913.10"/>
    </inertial>
  </link>

  <link name="RL_calf">
    <visual>
      <origin rpy="0 0 0" xyz="-0.036 0 0"/>
      <geometry>
	<mesh filename="package://stuart_urdf/meshes/calflink.stl" scale="0.001 0.001 0.001"/>
      </geometry>
      <material name="silver"/>
    </visual>
    <collision>
      <origin rpy="0 0 0" xyz="-0.036 0 0"/>
      <geometry>
	<box size="0.04 0.04 0.04"/>
      </geometry>
    </collision>
    <inertial>
      <origin rpy="0 0 0" xyz="0 0 0"/>
      <mass value="0.00379"/>
      <inertia ixx="1454.94" ixy="-784.08" ixz="-18.54" iyy="475.55" iyz="34.08" izz="1913.10"/>
    </inertial>
  </link>

  <link name="RR_calf">
    <visual>
      <origin rpy="0 0 0" xyz="-0.036 0 0"/>
      <geometry>
	<mesh filename="package://stuart_urdf/meshes/calflink.stl" scale="0.001 0.001 0.001"/>
      </geometry>
      <material name="silver"/>
    </visual>
    <collision>
      <origin rpy="0 0 0" xyz="-0.036 0 0"/>
      <geometry>
	<box size="0.04 0.04 0.04"/>
      </geometry>
    </collision>
    <inertial>
      <origin rpy="0 0 0" xyz="0 0 0"/>
      <mass value="0.00379"/>
      <inertia ixx="1454.94" ixy="-784.08" ixz="-18.54" iyy="475.55" iyz="34.08" izz="1913.10"/>
    </inertial>
  </link>

  <joint name="FLthigh_calf" type="revolute">
    <parent link="FL_thigh"/>
    <child link="FL_calf"/>
    <origin rpy="0 0 0" xyz="-0.060 0.005 0"/>
    <axis xyz="0 1 0"/>
    <dynamics damping="0" friction="0"/>
    <limit effort="100" lower="-3.14" upper="3.14" velocity="100"/>
  </joint>
  <joint name="FRthigh_calf" type="revolute">
    <parent link="FR_thigh"/>
    <child link="FR_calf"/>
    <origin rpy="0 0 0" xyz="-0.060 -0.005 0"/>
    <axis xyz="0 1 0"/>
    <dynamics damping="0" friction="0"/>
    <limit effort="100" lower="-3.14" upper="3.14" velocity="100"/>
  </joint>
  <joint name="RLthigh_calf" type="revolute">
    <parent link="RL_thigh"/>
    <child link="RL_calf"/>
    <origin rpy="0 0 0" xyz="-0.060 0.005 0"/>
    <axis xyz="0 1 0"/>
    <dynamics damping="0" friction="0"/>
    <limit effort="100" lower="-3.14" upper="3.14" velocity="100"/>
  </joint>
  <joint name="RRthigh_calf" type="revolute">
    <parent link="RR_thigh"/>
    <child link="RR_calf"/>
    <origin rpy="0 0 0" xyz="-0.060 -0.005 0"/>
    <axis xyz="0 1 0"/>
    <dynamics damping="0" friction="0"/>
    <limit effort="100" lower="-3.14" upper="3.14" velocity="100"/>
  </joint>




  <link name="FL_foot">
    <visual>
      <origin rpy="0 1.57 0" xyz="-0.0058 0 0"/>
      <geometry>
	<mesh filename="package://stuart_urdf/meshes/foot.stl" scale="0.001 0.001 0.001"/>
      </geometry>
      <material name="silver"/>
    </visual>
    <collision>
      <origin rpy="0 0 0" xyz="-0.0058 0 0"/>
      <geometry>
	<box size="0.015 0.02 0.04"/>
      </geometry>
      <surface>
        <friction>
          <ode>
            <mu>10000.0</mu>
            <mu2>10000.0</mu2>
          </ode>
        </friction>
      </surface>
    </collision>
    <inertial>
      <origin rpy="0 0 0" xyz="0 0 0"/>
      <mass value="0.00566"/>
      <inertia ixx="313.77" ixy="-72.59" ixz="-1.23" iyy="938.81" iyz="-3.47" izz="799.53"/>
    </inertial>
  </link>

  <link name="FR_foot">
    <visual>
      <origin rpy="0 1.57 0" xyz="-0.0058 0 0"/>
      <geometry>
	<mesh filename="package://stuart_urdf/meshes/foot.stl" scale="0.001 0.001 0.001"/>
      </geometry>
      <material name="silver"/>
    </visual>
    <collision>
      <origin rpy="0 0 0" xyz="-0.0058 0 0"/>
      <geometry>
	<box size="0.015 0.02 0.04"/>
      </geometry>
      <surface>
        <friction>
          <ode>
            <mu>10000.0</mu>
            <mu2>10000.0</mu2>
          </ode>
        </friction>
      </surface>
    </collision>
    <inertial>
      <origin rpy="0 0 0" xyz="0 0 0"/>
      <mass value="0.00566"/>
      <inertia ixx="313.77" ixy="-72.59" ixz="-1.23" iyy="938.81" iyz="-3.47" izz="799.53"/>
    </inertial>
  </link>

  <link name="RL_foot">
    <visual>
      <origin rpy="0 1.57 0" xyz="-0.0058 0 0"/>
      <geometry>
	<mesh filename="package://stuart_urdf/meshes/foot.stl" scale="0.001 0.001 0.001"/>
      </geometry>
      <material name="silver"/>
    </visual>
    <collision>
      <origin rpy="0 0 0" xyz="-0.0058 0 0"/>
      <geometry>
	<box size="0.015 0.02 0.04"/>
      </geometry>
      <surface>
        <friction>
          <ode>
            <mu>10000.0</mu>
            <mu2>10000.0</mu2>
          </ode>
        </friction>
      </surface>
    </collision>
    <inertial>
      <origin rpy="0 0 0" xyz="0 0 0"/>
      <mass value="0.00566"/>
      <inertia ixx="313.77" ixy="-72.59" ixz="-1.23" iyy="938.81" iyz="-3.47" izz="799.53"/>
    </inertial>
  </link>

  <link name="RR_foot">
    <visual>
      <origin rpy="0 1.57 0" xyz="-0.0058 0 0"/>
      <geometry>
	<mesh filename="package://stuart_urdf/meshes/foot.stl" scale="0.001 0.001 0.001"/>
      </geometry>
      <material name="silver"/>
    </visual>
    <collision>
      <origin rpy="0 0 0" xyz="-0.0058 0 0"/>
      <geometry>
	<box size="0.015 0.02 0.04"/>
      </geometry>
      <surface>
        <friction>
          <ode>
            <mu>10000.0</mu>
            <mu2>10000.0</mu2>
          </ode>
        </friction>
      </surface>
    </collision>
    <inertial>
      <origin rpy="0 0 0" xyz="0 0 0"/>
      <mass value="0.00566"/>
      <inertia ixx="313.77" ixy="-72.59" ixz="-1.23" iyy="938.81" iyz="-3.47" izz="799.53"/>
    </inertial>
  </link>


  <joint name="FLcalf_foot" type="continuous">
    <parent link="FL_calf"/>
    <child link="FL_foot"/>
    <origin rpy="0 0 0" xyz="-0.0702 0 0"/>
    <axis xyz="0 1 0"/>
    <dynamics damping="0" friction="0"/>
    <limit effort="0" velocity="100"/>
  </joint>
  <joint name="FRcalf_foot" type="continuous">
    <parent link="FR_calf"/>
    <child link="FR_foot"/>
    <origin rpy="0 0 0" xyz="-0.0702 0 0"/>
    <axis xyz="0 1 0"/>
    <dynamics damping="0" friction="0"/>
    <limit effort="0" velocity="100"/>
  </joint>
  <joint name="RLcalf_foot" type="continuous">
    <parent link="RL_calf"/>
    <child link="RL_foot"/>
    <origin rpy="0 0 0" xyz="-0.0702 0 0"/>
    <axis xyz="0 1 0"/>
    <dynamics damping="0" friction="0"/>
    <limit effort="0" velocity="100"/>
  </joint>
  <joint name="RRcalf_foot" type="continuous">
    <parent link="RR_calf"/>
    <child link="RR_foot"/>
    <origin rpy="0 0 0" xyz="-0.0702 0 0"/>
    <axis xyz="0 1 0"/>
    <dynamics damping="0" friction="0"/>
    <limit effort="0" velocity="100"/>
  </joint>





  <link name="tailmotor">
    <visual>
      <origin rpy="0 0 0" xyz="0 0 0"/>
      <geometry>
	<mesh filename="package://stuart_urdf/meshes/tailmotor.stl" scale="0.001 0.001 0.001"/>
      </geometry>
      <material name="silver"/>
    </visual>
    <collision>
      <origin rpy="0 0 0" xyz="0 0 0"/>
      <geometry>
	<box size="0.04 0.04 0.04"/>
      </geometry>
    </collision>
    <inertial>
      <origin rpy="0 0 0" xyz="0 0 0"/>
      <mass value="0.069"/>
      <inertia ixx="14153.08" ixy="23.16" ixz="17.39" iyy="19823.76" iyz="1.78" izz="12751.31"/>
    </inertial>
  </link>

  <joint name="chassis_tailmotor" type="fixed">
    <parent link="chassis"/>
    <child link="tailmotor"/>
    <origin rpy="0 0 0" xyz="-0.082 -0.0018 0.0156"/>
  </joint>





  <link name="tail">
    <visual>
      <origin rpy="0 0 0" xyz="-0.0057 0 0.0115"/>
      <geometry>
	<mesh filename="package://stuart_urdf/meshes/taillink.stl" scale="0.001 0.001 0.001"/>
      </geometry>
      <material name="silver"/>
    </visual>
    <collision>
      <origin rpy="0 0.55 0" xyz="-0.0807 0 0.0865"/>
      <geometry>
	<box size="0.06 0.04 0.02"/>
      </geometry>
    </collision>
    <inertial>
      <origin rpy="0 0 0" xyz="0 0 0"/>
      <mass value="0.050"/>
      <inertia ixx="47638.27" ixy="-52093.80" ixz="0.0" iyy="87405.18" iyz="0.0" izz="115104.93"/>
    </inertial>
  </link>

  <joint name="tailmotor_tail" type="revolute">
    <parent link="tailmotor"/>
    <child link="tail"/>
    <origin rpy="0 0 0" xyz="-0.0033 0.002 0.0023"/>
    <axis xyz="0 1 0"/>
    <dynamics damping="0" friction="0"/>
    <limit effort="100" lower="-3.14" upper="3.14" velocity="100"/>
  </joint>



  <!--<link name="tail2">
    <visual>
      <origin rpy="0 0.55 0" xyz="-0.0807 0 0.0865"/>
      <geometry>
	<box size="0.06 0.04 0.02"/>
      </geometry>
      <material name="green"/>
    </visual>
    <collision>
      <origin rpy="0 0 0" xyz="0 0 0"/>
      <geometry>
	<box size="0.04 0.04 0.04"/>
      </geometry>
    </collision>
    <inertial>
      <origin rpy="0 0 0" xyz="0.002284 -4.1e-05 0.025165"/>
      <mass value="0.00379"/>
      <inertia ixx="0.073348887" ixy="0.00030338" ixz="0.001918218" iyy="0.250684593" iyz="-7.5402e-05" izz="0.254469458"/>
    </inertial>
  </link>

  <joint name="tailmotor_tail2" type="revolute">
    <parent link="tailmotor"/>
    <child link="tail2"/>
    <origin rpy="0 0 0" xyz="-0.0033 0.002 0.0023"/>
    <axis xyz="0 1 0"/>
    <dynamics damping="0" friction="0"/>
    <limit effort="100" lower="-3.14" upper="3.14" velocity="100"/>
  </joint>-->






  <link name="realsense_assembly">
    <visual>
      <origin rpy="0 0 0" xyz="0 0 0"/>
      <geometry>
	<mesh filename="package://stuart_urdf/meshes/realsenseassembly.stl" scale="0.001 0.001 0.001"/>
      </geometry>
      <material name="silver"/>
    </visual>
    <collision>
      <origin rpy="0 0 0" xyz="0 0 0"/>
      <geometry>
        <box size="0.06 0.09 0.015"/>
      </geometry>
    </collision>
    <inertial>
      <origin rpy="0 0 0" xyz="0 0 0"/>
      <mass value="0.186"/>
      <inertia ixx="7808248.0" ixy="-9493.498047" ixz="-26793.921875" iyy="6664380.0" iyz="-677.709412" izz="11033013.0"/>
    </inertial>
  </link>
  <joint name="chassis_realsense" type="fixed">
    <parent link="chassis"/>
    <child link="realsense_assembly"/>
    <origin rpy="0 0 0" xyz="0.0375 -0.005 -0.0625"/>
    <axis xyz="0 0 0"/>
    <dynamics damping="0" friction="0"/>
    <limit effort="100" velocity="100"/>
  </joint>











  <link name="pi">
    <visual>
      <origin rpy="0 0 0" xyz="0 0 0"/>
      <geometry>
	<box size="0.06 0.09 0.015"/>
      </geometry>
      <material name="silver"/>
    </visual>
    <collision>
      <origin rpy="0 0 0" xyz="0 0 0"/>
      <geometry>
        <box size="0.06 0.09 0.015"/>
      </geometry>
    </collision>
    <inertial>
      <origin rpy="0 0 0" xyz="0 0 0"/>
      <mass value="0.045"/>
      <inertia ixx="30425.73" ixy="69.53" ixz="-262.76" iyy="41413.53" iyz="-3133.23" izz="13177.95"/>
    </inertial>
  </link>
  <joint name="pi_chassis" type="fixed">
    <parent link="chassis"/>
    <child link="pi"/>
    <origin rpy="0 0 0" xyz="0.015 0 0.0205"/>
    <axis xyz="0 0 0"/>
    <dynamics damping="0" friction="0"/>
    <limit effort="100" velocity="100"/>
  </joint>

  <link name="imu">
    <visual>
      <origin rpy="0 0 0" xyz="0 0 0"/>
      <geometry>
	<box size="0.051 0.036 0.015"/>
      </geometry>
      <material name="silver"/>
    </visual>
    <collision>
      <origin rpy="0 0 0" xyz="0 0 0"/>
      <geometry>
        <box size="0.051 0.036 0.015"/>
      </geometry>
    </collision>
    <inertial>
      <origin rpy="0 0 0" xyz="0 0 0"/>
      <mass value="0.05"/>
      <inertia ixx="6443.75" ixy="0.11" ixz="9.83" iyy="12351.05" iyz="-0.04" izz="7814.72"/>
    </inertial>
  </link>
  <joint name="imu_chassis" type="fixed">
    <parent link="chassis"/>
    <child link="imu"/>
    <origin rpy="0 0 0" xyz="0.07335 0 0.0105"/>
    <axis xyz="0 0 0"/>
    <dynamics damping="0" friction="0"/>
    <limit effort="100" velocity="100"/>
  </joint>

  <link name="servodriver">
    <visual>
      <origin rpy="0 0 0" xyz="0 0 0"/>
      <geometry>
	<box size="0.024 0.06 0.015"/>
      </geometry>
      <material name="silver"/>
    </visual>
    <collision>
      <origin rpy="0 0 0" xyz="0 0 0"/>
      <geometry>
        <box size="0.024 0.06 0.015"/>
      </geometry>
    </collision>
    <inertial>
      <origin rpy="0 0 0" xyz="0 0 0"/>
      <mass value="0.009"/>
      <inertia ixx="2606.32" ixy="-74.66" ixz="-208.49" iyy="3072.69" iyz="135.27" izz="648.61"/>
    </inertial>
  </link>
  <joint name="servodriver_chassis" type="fixed">
    <parent link="chassis"/>
    <child link="servodriver"/>
    <origin rpy="0 0 0" xyz="-0.036 0 0.0205"/>
    <axis xyz="0 0 0"/>
    <dynamics damping="0" friction="0"/>
    <limit effort="100" velocity="100"/>
  </joint>




































  <link name="imu_link">
    <inertial>
      <mass value="0.01"/>
      <origin xyz="0 0 0"/>
      <inertia ixx="0.000001" ixy="0" ixz="0" iyy="0.000001" iyz="0" izz="0.000001"/>
    </inertial>
    <visual>
      <origin rpy="0 0 0" xyz="0 0 0"/>
      <geometry>
        <box size="0.01 0.01 0.01"/>
      </geometry>
    </visual>
  </link>
  <joint name="imu_joint" type="fixed">
    <origin rpy="3.14159265359 0 0" xyz="0 0 0"/>
    <parent link="chassis"/>
    <child link="imu_link"/>
  </joint>

  <gazebo reference="imu_link">
    <sensor name="imu_link" type="imu">
      <always_on>1</always_on>
      <update_rate>500</update_rate>
      <visualize>true</visualize>
      <topic>__default_topic__</topic>
      <imu>

      </imu>
    </sensor>
  </gazebo>
  <gazebo>
    <plugin filename="libGazeboXBotPlugin.so" name="xbot_plugin_handler">
      <path_to_config_file>configs/stuart/configs/stuart.yaml</path_to_config_file>
    </plugin>
  </gazebo>
  <origin rpy="0 0 0" xyz="0.0 0.0 0.20"/>



</robot>

